Workbook

Sheet Índice de Citabilidade
A1: ULTRAVIS — Índice de Citabilidade (IC)
A2: Nota de 0 a 100 que mede o quanto você fez para ser citável — o gêmeo acionável da Visibilidade. Cada ponto é uma alavanca que o cliente controla. Soma ponderada de 6 dimensões, ordenadas de interno → externo. Pesos-prior sujeitos a calibração empírica contra a Visibilidade observada.
A3: IC = 0,22 · Open Media & AI Sources + 0,20 · Conteúdo + 0,18 · Customer Reviews + 0,15 · Legibilidade do Site + 0,13 · Verticals/Segments/Regulators + 0,12 · Social Presence
A5: As 6 dimensões · do que você controla ao que você conquista
A6: # | B6: Dimensão | C6: Frente | D6: Zona de ação | E6: Peso | F6: O que mede
A7: 01 | B7: Legibilidade do Site | C7: Site próprio | D7: Você controla sozinho | E7: 0.15 | F7: Prontidão técnica e entidade — schema/JSON-LD, llms.txt, sitemap, Wikidata/Wikipedia, headings e resposta no topo.
A8: 02 | B8: Conteúdo | C8: Site próprio | D8: Você controla sozinho | E8: 0.2 | F8: Cobertura + qualidade GEO por tópico — página própria e extraível: resposta no topo, estatísticas com fonte, blocos curtos.
A9: 03 | B9: Social Presence | C9: Redes sociais | D9: Você ativa / reivindica | E9: 0.12 | F9: Pegada multiplataforma e frescor — presença ativa em 4+ canais (destaque YouTube) e cadência recente.
A10: 04 | B10: Customer Reviews | C10: Voz dos clientes | D10: Você ativa / reivindica | E10: 0.18 | F10: Prova social e voz do cliente — G2, Trustpilot, Capterra, Reclame Aqui, Google Reviews e menções em Reddit/Quora.
A11: 05 | B11: Open Media & AI Sources | C11: Mídia e PR | D11: Você conquista no tempo | E11: 0.22 | F11: Presença nos domínios que as IAs citam — mídia earned, editorial, fóruns, diretórios e listagens do setor.
A12: 06 | B12: Verticals/Segments/Regulators | C12: Segmento | D12: Você conquista no tempo | E12: 0.13 | F12: Autoridade na vertical — reguladores e referências do setor, associações, listas "melhores/alternativas a" e demanda de marca.
A13: Peso total | E13: =SUM(E7:E12) -> 1 | F13: deve somar 100%
A15: Simulador de Score
A16: Preencha apenas a coluna Nota (0–100, células amarelas) e a Evidência. Critérios de cada nota: passe o mouse na célula ou veja a aba 'Critérios de Nota'.
B17: Dimensão | C17: Peso | D17: Nota (0–100) | E17: Contribuição | F17: Evidência (fonte da nota)
A18: 01 | B18: Legibilidade do Site | C18: =E7 -> 0.15 | D18: 60 | E18: =C18*D18 -> 9 | F18: Org schema em 8/10 páginas; sem llms.txt (crawl 2026-08)
A19: 02 | B19: Conteúdo | C19: =E8 -> 0.2 | D19: 72 | E19: =C19*D19 -> 14.4 | F19: 14/20 tópicos com página; ~60% front-load (auditoria de conteúdo)
A20: 03 | B20: Social Presence | C20: =E9 -> 0.12 | D20: 45 | E20: =C20*D20 -> 5.4 | F20: 4 canais ativos; YouTube parado há ~2 meses
A21: 04 | B21: Customer Reviews | C21: =E10 -> 0.18 | D21: 55 | E21: =C21*D21 -> 9.9 | F21: G2 4,3 (120 reviews); Trustpilot 4,1; Reclame Aqui respondido
A22: 05 | B22: Open Media & AI Sources | C22: =E11 -> 0.22 | D22: 30 | E22: =C22*D22 -> 6.6 | F22: presente em 9/24 domínios citados (Ahrefs + aba Citações)
A23: 06 | B23: Verticals/Segments/Regulators | C23: =E12 -> 0.13 | D23: 48 | E23: =C23*D23 -> 6.24 | F23: busca de marca 2,4k/mês; em 2 listas 'alternativas a'; sem Wikipedia
B24: IC (0–100) | D24: = | E24: =SUM(E18:E23) -> 51.54 | F24: soma das contribuições (média ponderada das notas)

Sheet Critérios de Nota
A1: ULTRAVIS — Critérios de Nota (0 a 100) por dimensão
A2: Cada nota ancora num sinal mensurável — registre a evidência ao dar a nota. Citabilidade é auditada dos seus ativos (crawler, Ahrefs, checagem de perfis); Visibilidade é lida das respostas de IA sobre um prompt-set fixo × motores. Faixas e thresholds são pontos de partida, a calibrar.
A4: CITABILIDADE — alavancas (você age · medido dos seus ativos)
A5: Dimensão | B5: Sinal medido | C5: 0–20 | D5: 21–40 | E5: 41–60 | F5: 61–80 | G5: 81–100
A6: 01 · Legibilidade do Site | B6: Cobertura de JSON-LD válido, llms.txt+sitemap, headings, entidade (Wikidata/Wikipedia) e nome/aliases consistentes | C6: Sem schema, sem llms.txt/sitemap, headings caóticos, sem entidade — a máquina não lê nem te identifica | D6: Só sitemap; schema ausente ou inválido em poucas páginas; sem entidade | E6: Organization schema válido nas páginas-chave, sitemap ok, headings razoáveis; sem Product/FAQ, sem llms.txt, entidade fraca | F6: Schema Org+Product+FAQ na maioria das páginas, llms.txt presente, headings limpos + resposta-no-topo; entidade com nome/aliases inconsistentes | G6: JSON-LD completo e validado (Org/Product/FAQ/Review), llms.txt+sitemap, resposta-no-topo impecável, entidade no Wikidata/Wikipedia com aliases consistentes
A7: 02 · Conteúdo | B7: Cobertura (% dos tópicos com página própria) × qualidade GEO (resposta nos ~30% iniciais, estatística com fonte, tabelas, blocos 50-150 palavras, <12 meses) | C7: <20% dos tópicos com página; páginas não extraíveis (paredão de texto, sem dados/fonte, resposta enterrada) | D7: 20-40% cobertos; qualidade GEO fraca | E7: 40-60% cobertos; algumas páginas front-load a resposta, estatísticas ocasionais com fonte | F7: 60-80% cobertos; maioria resposta-no-topo, cita estatística/fonte, algumas tabelas, majoritariamente fresco | G7: ≥80% com página dedicada; resposta nos ~30% iniciais, dados com fonte, citações de especialista, tabelas, blocos 50-150 palavras, <12 meses
A8: 03 · Social Presence | B8: Nº de plataformas ativas (satura em 5), recência/cadência, bônus YouTube | C8: 0-1 plataforma, dormente | D8: 2 plataformas, posts esporádicos (>3 meses parado) | E8: 3 plataformas ativas, cadência mensal, sem YouTube | F8: 4 plataformas, recente (últimas semanas), inclui YouTube | G8: 5 plataformas consistentemente ativas, cadência semanal+, YouTube forte, conteúdo do site reaproveitado
A9: 04 · Customer Reviews | B9: Presença/nota/volume/recência nas plataformas do seu mercado + menções em Reddit/Quora | C9: Sem perfis reivindicados; sem reviews ou negativos sem resposta | D9: Perfil em 1 plataforma, volume baixo, datado, nota <3,5 | E9: Perfis em 2-3 plataformas relevantes, volume moderado, nota ~4,0, algumas respostas | F9: Perfis completos nas plataformas-chave, nota ≥4,2, reviews recentes constantes, reclamações respondidas, alguma presença Reddit/Quora | G9: Presença forte + nota ≥4,5 + alto volume recente em G2/Trustpilot/etc + threads ativas e positivas em Reddit/Quora
A10: 05 · Open Media & AI Sources | B10: % dos domínios que as IAs citam no seu mercado onde você aparece (ponderado pela frequência de citação) + refdomains | C10: Presente em <10% dos domínios citados; poucos refdomains | D10: 10-25% dos domínios citados | E10: 25-50% — presente em fontes de frequência média | F10: 50-75%, incluindo vários domínios de alta frequência de citação; refdomains saudáveis | G10: ≥75% ponderado pela frequência; presente nos domínios mais citados; grande footprint de refdomains
A11: 06 · Verticals/Segments/Regulators | B11: Demanda de marca (volume de busca — correlato mais forte, r≈0,334), presença em reguladores/associações/listas 'melhores/alternativas a', Wikipedia | C11: Marca desconhecida (busca de marca ~0), ausente de reguladores/associações/listas | D11: Pequena busca de marca, sem listagens de vertical | E11: Demanda de marca moderada, em algumas listas 'melhores/alternativas a' | F11: Busca de marca sólida, membro de associações-chave, aparece em várias listas/referências da vertical | G11: Forte demanda de marca + reguladores/normas + associações + Wikipedia + listas 'top do setor'
A13: VISIBILIDADE / SCORE — resultado (você mede · lido das respostas de IA)
A14: Dimensão | B14: Sinal medido | C14: 0–20 | D14: 21–40 | E14: 41–60 | F14: 61–80 | G14: 81–100
A15: Citação | B15: Nível de menção médio (não cita → cita → recomenda → lidera), sobre o prompt-set fixo × motores | C15: Praticamente não mencionada nos prompts | D15: Mencionada só pelo nome, ocasionalmente | E15: Mencionada na maioria dos prompts relevantes, às vezes descrita | F15: Ativamente recomendada em muitas respostas | G15: Lidera / é a recomendação principal, consistente entre prompts e motores
A16: Presença | B16: Em quantos motores você aparece (cross-engine) | C16: Aparece em 0-1 motor | D16: 2 motores | E16: 3-4 motores | F16: 5 motores / maioria | G16: Todos os motores (6/6 ou 9/9), com consistência cross-engine
A17: Autoridade | B17: Profundidade do contexto quando citada | C17: Só o nome, sem contexto | D17: Nome + descritor genérico de uma linha | E17: Descreve a categoria / o que você faz | F17: Descreve diferenciais e produtos com precisão | G17: Narrativa rica e precisa — diferenciais, produtos, história, posicionamento
A18: Posição | B18: Posição média quando citada na resposta | C18: Citada em 5º ou pior | D18: ~4º | E18: ~3º | F18: ~2º | G18: ~1º de forma consistente
A19: Acurácia | B19: Correção factual / taxa de alucinação | C19: Alucina/erra fatos sobre a marca com frequência | D19: Várias imprecisões | E19: Majoritariamente correto, alguns dados desatualizados/erros menores | F19: Preciso, raros deslizes menores | G19: Totalmente preciso e atual, sem alucinação
A20: Sentimento | B20: Tom da citação | C20: Predominantemente negativo | D20: Misto puxando para negativo | E20: Neutro | F20: Majoritariamente positivo | G20: Consistentemente positivo / recomendação entusiasta

Sheet Ponte IC × Score
A1: ULTRAVIS — Ponte: Índice de Citabilidade (alavanca) × Score / Visibilidade (resultado)
A2: Cada ● indica que a alavanca (linha) move aquela dimensão do Score (coluna). Cor do ● = zona de ação. Crosswalk qualitativo — confiança média, a ser confirmado/corrigido pela calibração por regressão do IC contra a Visibilidade observada.
A4: Alavanca (IC) ↓ / Dimensão do Score → | B4: Peso IC | C4: Citação 20% Score | D4: Presença 20% Score | E4: Autoridade 20% Score | F4: Posição 15% Score | G4: Acurácia 15% Score | H4: Sentimento 10% Score | I4: Dimensões movidas
A5: 01 · Legibilidade do Site | B5: ='Índice de Citabilidade'!E7 -> 0.15 | D5: ● | E5: ● | G5: ● | I5: =COUNTIF(C5:H5,"●") -> 3
A6: 02 · Conteúdo | B6: ='Índice de Citabilidade'!E8 -> 0.2 | E6: ● | F6: ● | G6: ● | I6: =COUNTIF(C6:H6,"●") -> 3
A7: 03 · Social Presence | B7: ='Índice de Citabilidade'!E9 -> 0.12 | D7: ● | H7: ● | I7: =COUNTIF(C7:H7,"●") -> 2
A8: 04 · Customer Reviews | B8: ='Índice de Citabilidade'!E10 -> 0.18 | C8: ● | E8: ● | H8: ● | I8: =COUNTIF(C8:H8,"●") -> 3
A9: 05 · Open Media & AI Sources | B9: ='Índice de Citabilidade'!E11 -> 0.22 | C9: ● | D9: ● | F9: ● | I9: =COUNTIF(C9:H9,"●") -> 3
A10: 06 · Verticals/Segments/Regulators | B10: ='Índice de Citabilidade'!E12 -> 0.13 | C10: ● | E10: ● | I10: =COUNTIF(C10:H10,"●") -> 2
A11: Alavancas que movem a dimensão | C11: =COUNTIF(C5:C10,"●") -> 3 | D11: =COUNTIF(D5:D10,"●") -> 3 | E11: =COUNTIF(E5:E10,"●") -> 4 | F11: =COUNTIF(F5:F10,"●") -> 2 | G11: =COUNTIF(G5:G10,"●") -> 2 | H11: =COUNTIF(H5:H10,"●") -> 2 | I11: =SUM(I5:I10) -> 16
A13: Leitura: a maior alavanca (Open Media & AI Sources, 22% do IC) move Citação, Presença e Posição do Score. Autoridade é a dimensão mais "puxada" (4 alavancas). Ajuste os ● conforme a calibração empírica evoluir.

Sheet Draft-Estrutura e Comparativo
A1: ULTRAVIS · Comparativo de Pacotes — Visibilidade & Inteligência em IA
B2: SINAL/ SINAL | C2: ALCANCE/ REACH | D2: DOMÍNIO/ DOMAIN
A3: Valor Mensal | B3: R$15.000 /mês | C3: R$20.000 /mês | D3: R$30.000 /mês
A4: Categoria / Feature | B4: Entrada. Diagnóstico e Monitoramento. Todo mês | C4: Mais opções de prompts e relatórios mensais. Ultravis te ajuda a priorizar e customizar | D4: Domínio total. Conteúdo, monitoramento da concorrência, C-level. Briefings customizados | E4: Proposta de Valor para sua Marca ou Empresa de cada um dos elementos/ features
A5: DIAGNÓSTICO & MONITORAMENTO
A6: Frequência de diagnóstico | B6: Mensal | C6: Semanal | D6: Diário | E6: Em função da necessidade de atualização ou testes de prompts e posicionamento para usa Empresa ou Marca
A7: Motores de IA cobertos | B7: 4 | C7: 6 | D7: 9 | E7: Cobertura dos principais existentes: ChatGPT, Gemini, Claude, Google IO, Perplexity, Grok, CoPilot, DeepMind eMinimax
A8: Estimativa de potencial de retorno (em vendas) para seu negócio | B8: ✓ | C8: ✓ | D8: ✓ | E8: Range estimado e raciona de cálculo, a partir do impacto esperado em visibilidade, leads que resultariam em vendas após implantadas as correções e melhorias sugeridas
A9: Score report completo | B9: ✓ | C9: ✓ | D9: ✓ | E9: Ranking para os prompts considerados e abertura nas 6 dimensões do Score, com pontos positivos e o que é preciso ajustar
A10: Dashboard de monitoramento (nas 6 dimensões do Score) | B10: ✓ | C10: ✓ | D10: ✓ | E10: Visualização da evolução do Score e dimensões que o compõe, com indicação das principais mudanças
A11: Rede de Conhecimento | B11: ✓ | C11: ✓ | D11: ✓ | E11: Mapa visual de onde e por onde passam as IAs quando buscam informação de sua marca e seus concorrentes
A12: Kit Press Release - Conteúdo de Autoridade | B12: — | C12: ✓ | D12: ✓ | E12: Sugestão de conteúdo com headline, corpo, referência e canal a publicar para reforça a Autoridade da marca
A13: Alertas de variação de score | B13: ✓ | C13: ✓ | D13: ✓ | E13: alertas enviados via email ou whatsapp quando há uma alteração de mais de +/-5 pontos na sua nota ou dos concorrentes mapeados (função background semanal)
A14: Fale com o Orin | B14: ✓ | C14: ✓ | D14: ✓ | E14: Suporte online e real-time que você pode perguntar termos técnicos ou entendimento de elementos direto do relatório 24x7
A15: BRIEFING CUSTOMIZADO
A16: Resumo do briefing customizado para até 100 prompts definidos pelo cliente | B16: — | C16: — | D16: ✓ | E16: Verificação no relatório de que todo o briefing foi considerado e o retorno de cada IA para os prompts específicos
A17: ESTRATÉGIA & REPORTING
A18: Briefings de conteúdo | B18: ✓ | C18: ✓ | D18: ✓ | E18: Em CADA relatório, Sugestão de conteúdo e código para Blog, FAQ e outros para aprovação interna e consequente post/publicação
A19: Sessões de estratégia | B19: 1hr/mês | C19: 2–3h/mês | D19: Até 90 min semanais | E19: Consultoria com executivos Ultravis para entender e adequar prompts e posicionamento para a marca ou empresa, para que os relatórios sejam o mais específico possível
A20: Relatórios customizados | B20: — | C20: — | D20: ✓ | E20: A partir de uma página de Briefing com prompts específicos para o posicionamento da empresa ou marca, geração de relatórios adicionais
A21: Relatório executivo C-level | B21: — | C21: ✓ | D21: ✓ | E21: Resumo de principais pontos, visão das IAs sobre a marca e aumentar engajamento/ alinhamento Executivo do tema
A22: PERGUNTAS IA
A23: Share of voice em IA (Total, Direto e Orgânico) | B23: ✓ | C23: ✓ | D23: ✓ | E23: Entender o quanto as IAs citam você quando há consultas genéricas do segmento ou quando perguntam em específico sobre sua marca
A24: Tabela de visibilidade por motor de IA | B24: ✓ | C24: ✓ | D24: ✓ | E24: Score por cada uma das IAs de teu share of voice
A25: Resumo Teste LLMO O que a “IA sabe / IA não sabe” sobre a marca | B25: ✓ | C25: ✓ | D25: ✓ | E25: Resumo Executivo dos principais sobre o que as IAs sabem ou não para priorizar sua estratégia de posicionamento e melhorar alinhamento executivo na sua empresa
A26: Lista de Fontes que as IAs consultam | B26: ✓ | C26: ✓ | D26: ✓ | E26: Referência de onde a IA buscou e você precisa monitorar e se posicionar
A27: Lacunas das IAs | B27: ✓ | C27: ✓ | D27: ✓ | E27: Visibilidade dos prompts avaliados pelas IAs e se sua marca aparece ou não
A28: Teste em Tempo Real | B28: ✓ | C28: ✓ | D28: ✓ | E28: Digite uma pergunta e veja como cada IA responde em tempo real
A29: CONCORRENTES
A30: Comparação direta de sua nota nas 6 dimensões com o líder do segmento | B30: ✓ | C30: ✓ | D30: ✓ | E30: Entender como e onde o teu concorrente está melhor ou não
A31: Comparativo das 6 dimensões técnicas entre os concorrentes | B31: ✓ | C31: ✓ | D31: ✓ | E31: Quais as notas dos principais concorrentes, vs a sua por cada uma das 6 dimensões que compões o Index
A32: Tabela técnica resumo você vs os concorrentes (JSON, Schema, LLM.txt, FAQ, etc) | B32: ✓ | C32: ✓ | D32: ✓ | E32: Apresenta um resumo preliminar do status dos concorrentes vs você sobre atuação nestas dimensões
A33: Comparativo de produtos ou serviços com seus concorrentes | B33: — | C33: ✓ | D33: ✓ | E33: Comparativo de seus principais produtos e o Sentimento (recomendação) das IAs sobre quando/ porque escolher o seu vs o do concorrente
A34: AUDITORIA TÉCNICA (SITE DA MARCA)
A35: Itens técnicos
A36: Auditoria em 8 dimensões de teu site | B36: ✓ | C36: ✓ | D36: ✓ | E36: Resumo dos principais pontos a melhorar/ajustar no site da marca em relação a 8 dimensões (Rendering, Schema J-SON-LD, FAQ/Editorial, llms.txt, configuração de idioma/país, Página de produto sem título descritivo, meta tags sociais, Trust/reputação
A37: Social GEO Score | B37: ✓ | C37: ✓ | D37: ✓ | E37: Apresenta as fontes de informação complementares sobre sua marca que foram consultadas e qualidade técnica para leitura das IAs
A38: Auditoria de presença em fontes citadas pela IA | B38: — | C38: ✓ | D38: ✓
A39: Scan preliminar de comércio agêntico
A40: Scan preliminar de comércio agêntico (agentic commerce) | B40: ✓ | C40: ✓ | D40: ✓ | E40: Resumo Preliminar de problemas/ limitadores técnicos do site ao agentes de compra
...
